2025-09-26 00:19:21,364 | ERROR | restaurant_app | execute_query:2036 | Database operational error: no such column: user_id
2025-09-26 00:19:36,554 | ERROR | restaurant_app | execute_query:2036 | Database operational error: no such column: user_id
2025-09-26 00:19:43,298 | ERROR | restaurant_app | execute_query:2036 | Database operational error: no such column: user_id
2025-09-26 00:20:37,474 | ERROR | restaurant_app | execute_query:2036 | Database operational error: no such column: user_id
2025-09-26 00:27:30,075 | ERROR | restaurant_app | execute_query:2036 | Database operational error: no such column: user_id
2025-09-26 00:27:30,117 | ERROR | restaurant_app | execute_query:2036 | Database operational error: no such column: user_id
2025-09-26 00:27:30,126 | ERROR | restaurant_app | execute_query:2036 | Database operational error: no such column: user_id
2025-09-26 00:29:06,595 | ERROR | restaurant_app | execute_query:2036 | Database operational error: no such column: user_id
2025-09-26 00:29:12,375 | ERROR | restaurant_app | execute_query:2036 | Database operational error: no such column: user_id
2025-09-26 00:29:13,979 | ERROR | restaurant_app | execute_query:2036 | Database operational error: no such column: user_id
2025-09-26 00:29:17,532 | ERROR | restaurant_app | execute_query:2036 | Database operational error: no such column: user_id
2025-09-26 00:33:45,470 | ERROR | restaurant_app | execute_query:2036 | Database operational error: no such column: user_id
2025-09-26 00:34:02,529 | ERROR | restaurant_app | execute_query:2036 | Database operational error: no such column: user_id
2025-09-26 00:34:58,750 | ERROR | restaurant_app | execute_query:2036 | Database operational error: no such column: user_id
2025-09-26 00:35:03,443 | ERROR | restaurant_app | execute_query:2036 | Database operational error: no such column: user_id
2025-09-26 00:35:09,199 | ERROR | restaurant_app | execute_query:2036 | Database operational error: no such column: user_id
2025-09-26 14:10:40,758 | ERROR | restaurant_app | execute_query:2036 | Database operational error: no such column: user_id
2025-09-26 14:10:44,451 | ERROR | restaurant_app | execute_query:2036 | Database operational error: no such column: user_id
2025-09-26 14:10:44,475 | ERROR | restaurant_app | execute_query:2036 | Database operational error: no such column: user_id
2025-09-26 14:10:47,612 | ERROR | restaurant_app | execute_query:2036 | Database operational error: no such column: user_id
2025-09-26 14:10:47,930 | ERROR | restaurant_app | execute_query:2036 | Database operational error: no such column: user_id
2025-09-26 14:10:47,942 | ERROR | restaurant_app | execute_query:2036 | Database operational error: no such column: user_id
2025-09-26 14:10:51,692 | ERROR | restaurant_app | execute_query:2036 | Database operational error: no such column: user_id
2025-09-26 14:10:52,090 | ERROR | restaurant_app | execute_query:2036 | Database operational error: no such column: user_id
2025-09-26 14:10:52,096 | ERROR | restaurant_app | execute_query:2036 | Database operational error: no such column: user_id
2025-09-26 14:11:24,071 | ERROR | restaurant_app | execute_query:2036 | Database operational error: no such column: user_id
2025-09-26 14:11:25,841 | ERROR | restaurant_app | execute_query:2036 | Database operational error: no such column: user_id
2025-09-26 14:11:25,857 | ERROR | restaurant_app | execute_query:2036 | Database operational error: no such column: user_id
2025-09-26 14:12:49,424 | ERROR | restaurant_app | execute_query:2036 | Database operational error: no such column: user_id
2025-09-26 14:12:49,430 | ERROR | restaurant_app | execute_query:2036 | Database operational error: no such column: user_id
2025-09-26 14:12:56,949 | ERROR | restaurant_app | execute_query:2036 | Database operational error: no such column: user_id
2025-09-26 14:12:58,367 | ERROR | restaurant_app | execute_query:2036 | Database operational error: no such column: user_id
2025-09-26 14:12:58,369 | ERROR | restaurant_app | execute_query:2036 | Database operational error: no such column: user_id
2025-09-26 14:13:01,136 | ERROR | restaurant_app | execute_query:2036 | Database operational error: no such column: user_id
2025-09-26 14:13:01,156 | ERROR | restaurant_app | execute_query:2036 | Database operational error: no such column: user_id
2025-09-26 14:13:03,316 | ERROR | restaurant_app | execute_query:2036 | Database operational error: no such column: user_id
2025-09-26 14:13:03,627 | ERROR | restaurant_app | execute_query:2036 | Database operational error: no such column: user_id
2025-09-26 14:13:06,559 | ERROR | restaurant_app | execute_query:2036 | Database operational error: no such column: user_id
2025-09-26 14:13:07,893 | ERROR | restaurant_app | execute_query:2036 | Database operational error: no such column: user_id
2025-09-26 14:13:08,768 | ERROR | restaurant_app | execute_query:2036 | Database operational error: no such column: user_id
2025-09-26 14:13:08,775 | ERROR | restaurant_app | execute_query:2036 | Database operational error: no such column: user_id
2025-09-26 14:13:12,872 | ERROR | restaurant_app | execute_query:2036 | Database operational error: no such column: user_id
2025-09-26 14:13:13,355 | ERROR | restaurant_app | execute_query:2036 | Database operational error: no such column: user_id
2025-09-26 14:13:13,355 | ERROR | restaurant_app | execute_query:2036 | Database operational error: no such column: user_id
2025-09-26 14:24:20,844 | ERROR | werkzeug | _log:97 | Error on request:
Traceback (most recent call last):
  File "C:\Users\Moxir_Coder\AppData\Local\Programs\Python\Python311\Lib\site-packages\werkzeug\serving.py", line 370, in run_wsgi
    execute(self.server.app)
  File "C:\Users\Moxir_Coder\AppData\Local\Programs\Python\Python311\Lib\site-packages\werkzeug\serving.py", line 355, in execute
    data = self.rfile.read(10_000_000)
           ^^^^^^^^^^^^^^^^^^^^^^^^^^^
MemoryError
2025-09-26 15:11:01,330 | ERROR | restaurant_app | news_page:10334 | News page error: Could not build url for endpoint 'kafolatlar'. Did you mean 'kafolatlar_page' instead?
2025-09-26 15:11:01,351 | ERROR | restaurant_app | admin_news_management:15558 | News management page error: Could not build url for endpoint 'kafolatlar'. Did you mean 'kafolatlar_page' instead?
2025-09-26 15:11:01,434 | ERROR | restaurant_app | menu:6179 | Menu endpoint error: Could not build url for endpoint 'kafolatlar'. Did you mean 'kafolatlar_page' instead?
2025-09-26 15:11:01,453 | ERROR | restaurant_app | menu:6194 | Menu fallback error: Could not build url for endpoint 'kafolatlar'. Did you mean 'kafolatlar_page' instead?
2025-09-26 15:21:02,697 | ERROR | restaurant_app | execute_query:2055 | Database operational error: no such column: user_id
2025-09-26 15:21:02,765 | ERROR | restaurant_app | menu:6198 | Menu endpoint error: Could not build url for endpoint 'kafolatlar'. Did you mean 'kafolatlar_page' instead?
2025-09-26 15:21:02,767 | ERROR | restaurant_app | execute_query:2055 | Database operational error: no such column: user_id
2025-09-26 15:21:02,775 | ERROR | restaurant_app | menu:6213 | Menu fallback error: Could not build url for endpoint 'kafolatlar'. Did you mean 'kafolatlar_page' instead?
2025-09-26 15:21:14,040 | ERROR | restaurant_app | execute_query:2055 | Database operational error: no such column: user_id
2025-09-26 15:21:41,467 | ERROR | restaurant_app | execute_query:2056 | Database operational error: no such column: user_id
2025-09-26 15:21:41,531 | ERROR | restaurant_app | menu:6199 | Menu endpoint error: Could not build url for endpoint 'kafolatlar'. Did you mean 'kafolatlar_page' instead?
2025-09-26 15:21:41,532 | ERROR | restaurant_app | execute_query:2056 | Database operational error: no such column: user_id
2025-09-26 15:21:41,539 | ERROR | restaurant_app | menu:6214 | Menu fallback error: Could not build url for endpoint 'kafolatlar'. Did you mean 'kafolatlar_page' instead?
2025-09-26 15:22:47,432 | ERROR | restaurant_app | execute_query:2056 | Database operational error: no such column: user_id
2025-09-26 15:22:56,418 | ERROR | restaurant_app | execute_query:2056 | Database operational error: no such column: user_id
2025-09-26 15:22:56,484 | ERROR | restaurant_app | menu:6199 | Menu endpoint error: Could not build url for endpoint 'kafolatlar'. Did you mean 'kafolatlar_page' instead?
2025-09-26 15:22:56,485 | ERROR | restaurant_app | execute_query:2056 | Database operational error: no such column: user_id
2025-09-26 15:22:56,492 | ERROR | restaurant_app | menu:6214 | Menu fallback error: Could not build url for endpoint 'kafolatlar'. Did you mean 'kafolatlar_page' instead?
2025-09-26 15:29:33,844 | ERROR | restaurant_app | menu:6201 | Menu endpoint error: Could not build url for endpoint 'kafolatlar'. Did you mean 'kafolatlar_page' instead?
2025-09-26 15:29:33,853 | ERROR | restaurant_app | menu:6216 | Menu fallback error: Could not build url for endpoint 'kafolatlar'. Did you mean 'kafolatlar_page' instead?
2025-09-26 15:36:30,175 | ERROR | restaurant_app | menu:6201 | Menu endpoint error: Could not build url for endpoint 'kafolatlar'. Did you mean 'kafolatlar_page' instead?
2025-09-26 15:36:30,184 | ERROR | restaurant_app | menu:6216 | Menu fallback error: Could not build url for endpoint 'kafolatlar'. Did you mean 'kafolatlar_page' instead?
2025-09-26 15:36:43,752 | ERROR | restaurant_app | menu:6201 | Menu endpoint error: Could not build url for endpoint 'kafolatlar'. Did you mean 'kafolatlar_page' instead?
2025-09-26 15:36:43,761 | ERROR | restaurant_app | menu:6216 | Menu fallback error: Could not build url for endpoint 'kafolatlar'. Did you mean 'kafolatlar_page' instead?
2025-09-26 16:08:56,783 | ERROR | restaurant_app | cart:6763 | Cart sahifasida xatolik: Could not build url for endpoint 'kafolatlar_page'. Did you mean 'kafolatlar' instead?
2025-09-26 16:08:56,792 | ERROR | restaurant_app | handle_exception:1275 | Unhandled exception: Could not build url for endpoint 'kafolatlar_page'. Did you mean 'kafolatlar' instead? - URL: http://127.0.0.1:5000/cart
2025-09-26 16:09:01,775 | ERROR | restaurant_app | cart:6763 | Cart sahifasida xatolik: Could not build url for endpoint 'kafolatlar_page'. Did you mean 'kafolatlar' instead?
2025-09-26 16:09:01,783 | ERROR | restaurant_app | handle_exception:1275 | Unhandled exception: Could not build url for endpoint 'kafolatlar_page'. Did you mean 'kafolatlar' instead? - URL: http://127.0.0.1:5000/cart
2025-09-26 16:09:28,296 | ERROR | restaurant_app | cart:6763 | Cart sahifasida xatolik: Could not build url for endpoint 'kafolatlar_page'. Did you mean 'kafolatlar' instead?
2025-09-26 16:09:28,304 | ERROR | restaurant_app | handle_exception:1275 | Unhandled exception: Could not build url for endpoint 'kafolatlar_page'. Did you mean 'kafolatlar' instead? - URL: http://127.0.0.1:5000/cart
2025-09-26 16:09:29,972 | ERROR | restaurant_app | menu:6294 | Menu endpoint error: Could not build url for endpoint 'kafolatlar_page'. Did you mean 'kafolatlar' instead?
2025-09-26 16:09:29,980 | ERROR | restaurant_app | menu:6309 | Menu fallback error: Could not build url for endpoint 'kafolatlar_page'. Did you mean 'kafolatlar' instead?
2025-09-26 16:09:41,392 | ERROR | restaurant_app | handle_exception:1275 | Unhandled exception: Could not build url for endpoint 'kafolatlar_page'. Did you mean 'kafolatlar' instead? - URL: http://127.0.0.1:5000/settings
2025-09-26 16:09:43,457 | ERROR | restaurant_app | handle_exception:1275 | Unhandled exception: Could not build url for endpoint 'kafolatlar_page'. Did you mean 'kafolatlar' instead? - URL: http://127.0.0.1:5000/settings
2025-09-26 16:09:44,378 | ERROR | restaurant_app | news_page:10449 | News page error: Could not build url for endpoint 'kafolatlar_page'. Did you mean 'kafolatlar' instead?
2025-09-26 16:09:45,399 | ERROR | restaurant_app | handle_exception:1275 | Unhandled exception: Could not build url for endpoint 'kafolatlar_page'. Did you mean 'kafolatlar' instead? - URL: http://127.0.0.1:5000/settings
2025-09-26 17:15:20,540 | ERROR | werkzeug | _log:97 | Error on request:
Traceback (most recent call last):
  File "C:\Users\Moxir_Coder\AppData\Local\Programs\Python\Python311\Lib\site-packages\werkzeug\serving.py", line 370, in run_wsgi
    execute(self.server.app)
  File "C:\Users\Moxir_Coder\AppData\Local\Programs\Python\Python311\Lib\site-packages\werkzeug\serving.py", line 355, in execute
    data = self.rfile.read(10_000_000)
           ^^^^^^^^^^^^^^^^^^^^^^^^^^^
MemoryError
2025-09-28 00:07:07,292 | ERROR | restaurant_app | staff_login:13897 | Staff row dict conversion error: [digital envelope routines: EVP_PBE_scrypt] malloc failure
2025-09-28 00:33:32,033 | ERROR | werkzeug | _log:97 | Error on request:
Traceback (most recent call last):
  File "C:\Users\Moxir_Coder\AppData\Local\Programs\Python\Python311\Lib\site-packages\werkzeug\serving.py", line 370, in run_wsgi
    execute(self.server.app)
  File "C:\Users\Moxir_Coder\AppData\Local\Programs\Python\Python311\Lib\site-packages\werkzeug\serving.py", line 355, in execute
    data = self.rfile.read(10_000_000)
           ^^^^^^^^^^^^^^^^^^^^^^^^^^^
MemoryError
2025-09-28 00:33:32,033 | ERROR | werkzeug | _log:97 | Error on request:
Traceback (most recent call last):
  File "C:\Users\Moxir_Coder\AppData\Local\Programs\Python\Python311\Lib\site-packages\werkzeug\serving.py", line 370, in run_wsgi
    execute(self.server.app)
  File "C:\Users\Moxir_Coder\AppData\Local\Programs\Python\Python311\Lib\site-packages\werkzeug\serving.py", line 355, in execute
    data = self.rfile.read(10_000_000)
           ^^^^^^^^^^^^^^^^^^^^^^^^^^^
MemoryError
2025-09-28 00:33:32,034 | ERROR | werkzeug | _log:97 | Error on request:
Traceback (most recent call last):
  File "C:\Users\Moxir_Coder\AppData\Local\Programs\Python\Python311\Lib\site-packages\werkzeug\serving.py", line 370, in run_wsgi
    execute(self.server.app)
  File "C:\Users\Moxir_Coder\AppData\Local\Programs\Python\Python311\Lib\site-packages\werkzeug\serving.py", line 355, in execute
    data = self.rfile.read(10_000_000)
           ^^^^^^^^^^^^^^^^^^^^^^^^^^^
MemoryError
2025-09-28 13:44:03,323 | ERROR | restaurant_app | handle_exception:1231 | Unhandled exception: name 'hashlib' is not defined - URL: http://127.0.0.1:5000/menu
2025-09-28 13:44:03,329 | ERROR | restaurant_app | handle_exception:1233 | Full traceback:
Traceback (most recent call last):
  File "C:\Users\Moxir_Coder\AppData\Local\Programs\Python\Python311\Lib\site-packages\flask\app.py", line 917, in full_dispatch_request
    rv = self.dispatch_request()
         ^^^^^^^^^^^^^^^^^^^^^^^
  File "C:\Users\Moxir_Coder\AppData\Local\Programs\Python\Python311\Lib\site-packages\flask\app.py", line 902, in dispatch_request
    return self.ensure_sync(self.view_functions[rule.endpoint])(**view_args)  # type: ignore[no-any-return]
           ^^^^^^^^^^^^^^^^^^^^^^^^^^^^^^^^^^^^^^^^^^^^^^^^^^^^^^^^^^^^^^^^^
  File "C:\Users\Moxir_Coder\OneDrive\Desktop\Pro-Obuv\app.py", line 6009, in wrapper
    return f(*args, **kwargs)
           ^^^^^^^^^^^^^^^^^^
  File "C:\Users\Moxir_Coder\OneDrive\Desktop\Pro-Obuv\app.py", line 6023, in wrapper
    cache_key = f"{f.__name__}:{hashlib.md5(str(args + tuple(kwargs.items())).encode()).hexdigest()}"
                                ^^^^^^^
NameError: name 'hashlib' is not defined

2025-09-28 13:44:04,248 | ERROR | restaurant_app | handle_exception:1231 | Unhandled exception: name 'hashlib' is not defined - URL: http://127.0.0.1:5000/menu
2025-09-28 13:44:04,249 | ERROR | restaurant_app | handle_exception:1233 | Full traceback:
Traceback (most recent call last):
  File "C:\Users\Moxir_Coder\AppData\Local\Programs\Python\Python311\Lib\site-packages\flask\app.py", line 917, in full_dispatch_request
    rv = self.dispatch_request()
         ^^^^^^^^^^^^^^^^^^^^^^^
  File "C:\Users\Moxir_Coder\AppData\Local\Programs\Python\Python311\Lib\site-packages\flask\app.py", line 902, in dispatch_request
    return self.ensure_sync(self.view_functions[rule.endpoint])(**view_args)  # type: ignore[no-any-return]
           ^^^^^^^^^^^^^^^^^^^^^^^^^^^^^^^^^^^^^^^^^^^^^^^^^^^^^^^^^^^^^^^^^
  File "C:\Users\Moxir_Coder\OneDrive\Desktop\Pro-Obuv\app.py", line 6009, in wrapper
    return f(*args, **kwargs)
           ^^^^^^^^^^^^^^^^^^
  File "C:\Users\Moxir_Coder\OneDrive\Desktop\Pro-Obuv\app.py", line 6023, in wrapper
    cache_key = f"{f.__name__}:{hashlib.md5(str(args + tuple(kwargs.items())).encode()).hexdigest()}"
                                ^^^^^^^
NameError: name 'hashlib' is not defined

2025-09-28 13:44:43,016 | ERROR | restaurant_app | handle_exception:1231 | Unhandled exception: name 'hashlib' is not defined - URL: http://127.0.0.1:5000/menu
2025-09-28 13:44:43,022 | ERROR | restaurant_app | handle_exception:1233 | Full traceback:
Traceback (most recent call last):
  File "C:\Users\Moxir_Coder\AppData\Local\Programs\Python\Python311\Lib\site-packages\flask\app.py", line 917, in full_dispatch_request
    rv = self.dispatch_request()
         ^^^^^^^^^^^^^^^^^^^^^^^
  File "C:\Users\Moxir_Coder\AppData\Local\Programs\Python\Python311\Lib\site-packages\flask\app.py", line 902, in dispatch_request
    return self.ensure_sync(self.view_functions[rule.endpoint])(**view_args)  # type: ignore[no-any-return]
           ^^^^^^^^^^^^^^^^^^^^^^^^^^^^^^^^^^^^^^^^^^^^^^^^^^^^^^^^^^^^^^^^^
  File "C:\Users\Moxir_Coder\OneDrive\Desktop\Pro-Obuv\app.py", line 6009, in wrapper
    return f(*args, **kwargs)
           ^^^^^^^^^^^^^^^^^^
  File "C:\Users\Moxir_Coder\OneDrive\Desktop\Pro-Obuv\app.py", line 6023, in wrapper
    cache_key = f"{f.__name__}:{hashlib.md5(str(args + tuple(kwargs.items())).encode()).hexdigest()}"
                                ^^^^^^^
NameError: name 'hashlib' is not defined

2025-09-28 13:46:13,215 | ERROR | restaurant_app | handle_exception:1231 | Unhandled exception: name 'hashlib' is not defined - URL: http://127.0.0.1:8001/menu
2025-09-28 13:46:13,252 | ERROR | restaurant_app | handle_exception:1233 | Full traceback:
Traceback (most recent call last):
  File "C:\Users\Moxir_Coder\AppData\Local\Programs\Python\Python311\Lib\site-packages\flask\app.py", line 917, in full_dispatch_request
    rv = self.dispatch_request()
         ^^^^^^^^^^^^^^^^^^^^^^^
  File "C:\Users\Moxir_Coder\AppData\Local\Programs\Python\Python311\Lib\site-packages\flask\app.py", line 902, in dispatch_request
    return self.ensure_sync(self.view_functions[rule.endpoint])(**view_args)  # type: ignore[no-any-return]
           ^^^^^^^^^^^^^^^^^^^^^^^^^^^^^^^^^^^^^^^^^^^^^^^^^^^^^^^^^^^^^^^^^
  File "C:\Users\Moxir_Coder\OneDrive\Desktop\Pro-Obuv\app.py", line 6009, in wrapper
    return redirect(url_for("index"))
       ^^^^^^^^^^^^^^^^^^
  File "C:\Users\Moxir_Coder\OneDrive\Desktop\Pro-Obuv\app.py", line 6023, in wrapper
    # Cache key yaratish
                        
NameError: name 'hashlib' is not defined

2025-09-28 13:46:17,200 | ERROR | restaurant_app | staff_login:13997 | Staff row dict conversion error: name 'check_password_hash' is not defined
2025-09-28 13:46:19,808 | ERROR | restaurant_app | staff_login:13997 | Staff row dict conversion error: name 'check_password_hash' is not defined
2025-09-28 13:46:21,041 | ERROR | restaurant_app | staff_login:13997 | Staff row dict conversion error: name 'check_password_hash' is not defined
2025-09-28 13:46:23,568 | ERROR | restaurant_app | staff_login:13997 | Staff row dict conversion error: name 'check_password_hash' is not defined
2025-09-28 13:46:49,900 | ERROR | restaurant_app | staff_login:13997 | Staff row dict conversion error: name 'check_password_hash' is not defined
2025-09-28 13:46:54,870 | ERROR | restaurant_app | staff_login:13997 | Staff row dict conversion error: name 'check_password_hash' is not defined
2025-09-28 13:47:04,994 | ERROR | restaurant_app | staff_login:13997 | Staff row dict conversion error: name 'check_password_hash' is not defined
2025-09-28 14:18:54,269 | ERROR | werkzeug | _log:97 | Error on request:
Traceback (most recent call last):
  File "C:\Users\Moxir_Coder\AppData\Local\Programs\Python\Python311\Lib\site-packages\werkzeug\serving.py", line 370, in run_wsgi
    execute(self.server.app)
  File "C:\Users\Moxir_Coder\AppData\Local\Programs\Python\Python311\Lib\site-packages\werkzeug\serving.py", line 355, in execute
    data = self.rfile.read(10_000_000)
           ^^^^^^^^^^^^^^^^^^^^^^^^^^^
MemoryError
2025-09-28 14:22:35,847 | ERROR | restaurant_app | handle_exception:1262 | Unhandled exception: Encountered unknown tag 'comment'. Jinja was looking for the following tags: 'endblock'. The innermost block that needs to be closed is 'block'. - URL: http://127.0.0.1:5000/contact
2025-09-28 14:22:35,944 | ERROR | restaurant_app | handle_exception:1264 | Full traceback:
Traceback (most recent call last):
  File "C:\Users\Moxir_Coder\AppData\Local\Programs\Python\Python311\Lib\site-packages\flask\app.py", line 917, in full_dispatch_request
    rv = self.dispatch_request()
         ^^^^^^^^^^^^^^^^^^^^^^^
  File "C:\Users\Moxir_Coder\AppData\Local\Programs\Python\Python311\Lib\site-packages\flask\app.py", line 902, in dispatch_request
    return self.ensure_sync(self.view_functions[rule.endpoint])(**view_args)  # type: ignore[no-any-return]
           ^^^^^^^^^^^^^^^^^^^^^^^^^^^^^^^^^^^^^^^^^^^^^^^^^^^^^^^^^^^^^^^^^
  File "C:\Users\Moxir_Coder\OneDrive\Desktop\Pro-Obuv\app.py", line 8349, in contact
    return render_template("contact.html", current_page="contact")
           ^^^^^^^^^^^^^^^^^^^^^^^^^^^^^^^^^^^^^^^^^^^^^^^^^^^^^^^
  File "C:\Users\Moxir_Coder\AppData\Local\Programs\Python\Python311\Lib\site-packages\flask\templating.py", line 149, in render_template
    template = app.jinja_env.get_or_select_template(template_name_or_list)
               ^^^^^^^^^^^^^^^^^^^^^^^^^^^^^^^^^^^^^^^^^^^^^^^^^^^^^^^^^^^
  File "C:\Users\Moxir_Coder\AppData\Local\Programs\Python\Python311\Lib\site-packages\jinja2\environment.py", line 1087, in get_or_select_template
    return self.get_template(template_name_or_list, parent, globals)
           ^^^^^^^^^^^^^^^^^^^^^^^^^^^^^^^^^^^^^^^^^^^^^^^^^^^^^^^^^
  File "C:\Users\Moxir_Coder\AppData\Local\Programs\Python\Python311\Lib\site-packages\jinja2\environment.py", line 1016, in get_template
    return self._load_template(name, globals)
           ^^^^^^^^^^^^^^^^^^^^^^^^^^^^^^^^^^
  File "C:\Users\Moxir_Coder\AppData\Local\Programs\Python\Python311\Lib\site-packages\jinja2\environment.py", line 975, in _load_template
    template = self.loader.load(self, name, self.make_globals(globals))
               ^^^^^^^^^^^^^^^^^^^^^^^^^^^^^^^^^^^^^^^^^^^^^^^^^^^^^^^^
  File "C:\Users\Moxir_Coder\AppData\Local\Programs\Python\Python311\Lib\site-packages\jinja2\loaders.py", line 138, in load
    code = environment.compile(source, name, filename)
           ^^^^^^^^^^^^^^^^^^^^^^^^^^^^^^^^^^^^^^^^^^^
  File "C:\Users\Moxir_Coder\AppData\Local\Programs\Python\Python311\Lib\site-packages\jinja2\environment.py", line 771, in compile
    self.handle_exception(source=source_hint)
  File "C:\Users\Moxir_Coder\AppData\Local\Programs\Python\Python311\Lib\site-packages\jinja2\environment.py", line 942, in handle_exception
    raise rewrite_traceback_stack(source=source)
  File "C:\Users\Moxir_Coder\OneDrive\Desktop\Pro-Obuv\templates\contact.html", line 69, in template
    {% comment %} <div class="contact-item">
    ^^^^^^^^^^^^^^^^^^^^^^^^^
jinja2.exceptions.TemplateSyntaxError: Encountered unknown tag 'comment'. Jinja was looking for the following tags: 'endblock'. The innermost block that needs to be closed is 'block'.

2025-09-28 14:22:46,723 | ERROR | restaurant_app | handle_exception:1262 | Unhandled exception: Encountered unknown tag 'comment'. Jinja was looking for the following tags: 'endblock'. The innermost block that needs to be closed is 'block'. - URL: http://127.0.0.1:5000/contact
2025-09-28 14:22:46,725 | ERROR | restaurant_app | handle_exception:1264 | Full traceback:
Traceback (most recent call last):
  File "C:\Users\Moxir_Coder\AppData\Local\Programs\Python\Python311\Lib\site-packages\flask\app.py", line 917, in full_dispatch_request
    rv = self.dispatch_request()
         ^^^^^^^^^^^^^^^^^^^^^^^
  File "C:\Users\Moxir_Coder\AppData\Local\Programs\Python\Python311\Lib\site-packages\flask\app.py", line 902, in dispatch_request
    return self.ensure_sync(self.view_functions[rule.endpoint])(**view_args)  # type: ignore[no-any-return]
           ^^^^^^^^^^^^^^^^^^^^^^^^^^^^^^^^^^^^^^^^^^^^^^^^^^^^^^^^^^^^^^^^^
  File "C:\Users\Moxir_Coder\OneDrive\Desktop\Pro-Obuv\app.py", line 8349, in contact
    return render_template("contact.html", current_page="contact")
           ^^^^^^^^^^^^^^^^^^^^^^^^^^^^^^^^^^^^^^^^^^^^^^^^^^^^^^^
  File "C:\Users\Moxir_Coder\AppData\Local\Programs\Python\Python311\Lib\site-packages\flask\templating.py", line 149, in render_template
    template = app.jinja_env.get_or_select_template(template_name_or_list)
               ^^^^^^^^^^^^^^^^^^^^^^^^^^^^^^^^^^^^^^^^^^^^^^^^^^^^^^^^^^^
  File "C:\Users\Moxir_Coder\AppData\Local\Programs\Python\Python311\Lib\site-packages\jinja2\environment.py", line 1087, in get_or_select_template
    return self.get_template(template_name_or_list, parent, globals)
           ^^^^^^^^^^^^^^^^^^^^^^^^^^^^^^^^^^^^^^^^^^^^^^^^^^^^^^^^^
  File "C:\Users\Moxir_Coder\AppData\Local\Programs\Python\Python311\Lib\site-packages\jinja2\environment.py", line 1016, in get_template
    return self._load_template(name, globals)
           ^^^^^^^^^^^^^^^^^^^^^^^^^^^^^^^^^^
  File "C:\Users\Moxir_Coder\AppData\Local\Programs\Python\Python311\Lib\site-packages\jinja2\environment.py", line 975, in _load_template
    template = self.loader.load(self, name, self.make_globals(globals))
               ^^^^^^^^^^^^^^^^^^^^^^^^^^^^^^^^^^^^^^^^^^^^^^^^^^^^^^^^
  File "C:\Users\Moxir_Coder\AppData\Local\Programs\Python\Python311\Lib\site-packages\jinja2\loaders.py", line 138, in load
    code = environment.compile(source, name, filename)
           ^^^^^^^^^^^^^^^^^^^^^^^^^^^^^^^^^^^^^^^^^^^
  File "C:\Users\Moxir_Coder\AppData\Local\Programs\Python\Python311\Lib\site-packages\jinja2\environment.py", line 771, in compile
    self.handle_exception(source=source_hint)
  File "C:\Users\Moxir_Coder\AppData\Local\Programs\Python\Python311\Lib\site-packages\jinja2\environment.py", line 942, in handle_exception
    raise rewrite_traceback_stack(source=source)
  File "C:\Users\Moxir_Coder\OneDrive\Desktop\Pro-Obuv\templates\contact.html", line 69, in template
    {% comment %} <div class="contact-item">
    ^^^^^^^^^^^^^^^^^^^^^^^^^
jinja2.exceptions.TemplateSyntaxError: Encountered unknown tag 'comment'. Jinja was looking for the following tags: 'endblock'. The innermost block that needs to be closed is 'block'.

2025-09-28 14:34:16,695 | ERROR | restaurant_app | handle_exception:1262 | Unhandled exception: Could not build url for endpoint 'contect'. Did you mean 'contact' instead? - URL: http://127.0.0.1:5000/contact
2025-09-28 14:34:22,583 | ERROR | restaurant_app | handle_exception:1262 | Unhandled exception: Could not build url for endpoint 'contect'. Did you mean 'contact' instead? - URL: http://127.0.0.1:5000/contact
2025-09-28 14:34:38,397 | ERROR | restaurant_app | handle_exception:1262 | Unhandled exception: Could not build url for endpoint 'contect'. Did you mean 'contact' instead? - URL: http://127.0.0.1:5000/contact
2025-09-28 15:18:09,380 | ERROR | restaurant_app | api_super_admin_export_report:5739 | export-report error: name 'pd' is not defined - body_preview: b'{"branches":[],"customers":[],"products":[],"sales":[{"avg_order":720000,"cashback":0,"date":"2025-09-25","orders_count":1,"revenue":720000}],"staff":[],"summary":{"avg_check":720000,"growth_rate":-92.3,"new_customers":0,"total_orders":1,"total_revenue":720000}}'
2025-09-28 19:54:06,223 | ERROR | restaurant_app | super_admin_get_system_stats:13890 | System stats error: name 'start_time' is not defined
2025-09-28 21:50:28,252 | ERROR | werkzeug | _log:97 | Error on request:
Traceback (most recent call last):
  File "C:\Users\Moxir_Coder\AppData\Local\Programs\Python\Python311\Lib\site-packages\werkzeug\serving.py", line 370, in run_wsgi
    execute(self.server.app)
  File "C:\Users\Moxir_Coder\AppData\Local\Programs\Python\Python311\Lib\site-packages\werkzeug\serving.py", line 355, in execute
    data = self.rfile.read(10_000_000)
           ^^^^^^^^^^^^^^^^^^^^^^^^^^^
MemoryError
2025-09-28 21:50:28,627 | ERROR | werkzeug | _log:97 | Error on request:
Traceback (most recent call last):
  File "C:\Users\Moxir_Coder\AppData\Local\Programs\Python\Python311\Lib\site-packages\werkzeug\serving.py", line 370, in run_wsgi
    execute(self.server.app)
  File "C:\Users\Moxir_Coder\AppData\Local\Programs\Python\Python311\Lib\site-packages\werkzeug\serving.py", line 355, in execute
    data = self.rfile.read(10_000_000)
           ^^^^^^^^^^^^^^^^^^^^^^^^^^^
MemoryError
2025-09-28 21:50:28,664 | ERROR | werkzeug | _log:97 | Error on request:
Traceback (most recent call last):
  File "C:\Users\Moxir_Coder\AppData\Local\Programs\Python\Python311\Lib\site-packages\werkzeug\serving.py", line 370, in run_wsgi
    execute(self.server.app)
  File "C:\Users\Moxir_Coder\AppData\Local\Programs\Python\Python311\Lib\site-packages\werkzeug\serving.py", line 355, in execute
    data = self.rfile.read(10_000_000)
           ^^^^^^^^^^^^^^^^^^^^^^^^^^^
MemoryError
2025-09-28 21:50:28,675 | ERROR | werkzeug | _log:97 | Error on request:
Traceback (most recent call last):
  File "C:\Users\Moxir_Coder\AppData\Local\Programs\Python\Python311\Lib\site-packages\werkzeug\serving.py", line 370, in run_wsgi
    execute(self.server.app)
  File "C:\Users\Moxir_Coder\AppData\Local\Programs\Python\Python311\Lib\site-packages\werkzeug\serving.py", line 355, in execute
    data = self.rfile.read(10_000_000)
           ^^^^^^^^^^^^^^^^^^^^^^^^^^^
MemoryError
2025-09-28 21:50:28,687 | ERROR | werkzeug | _log:97 | Error on request:
Traceback (most recent call last):
  File "C:\Users\Moxir_Coder\AppData\Local\Programs\Python\Python311\Lib\site-packages\werkzeug\serving.py", line 370, in run_wsgi
    execute(self.server.app)
  File "C:\Users\Moxir_Coder\AppData\Local\Programs\Python\Python311\Lib\site-packages\werkzeug\serving.py", line 355, in execute
    data = self.rfile.read(10_000_000)
           ^^^^^^^^^^^^^^^^^^^^^^^^^^^
MemoryError
2025-09-28 21:50:28,700 | ERROR | werkzeug | _log:97 | Error on request:
Traceback (most recent call last):
  File "C:\Users\Moxir_Coder\AppData\Local\Programs\Python\Python311\Lib\site-packages\werkzeug\serving.py", line 370, in run_wsgi
    execute(self.server.app)
  File "C:\Users\Moxir_Coder\AppData\Local\Programs\Python\Python311\Lib\site-packages\werkzeug\serving.py", line 355, in execute
    data = self.rfile.read(10_000_000)
           ^^^^^^^^^^^^^^^^^^^^^^^^^^^
MemoryError
2025-09-28 21:50:28,720 | ERROR | werkzeug | _log:97 | Error on request:
Traceback (most recent call last):
  File "C:\Users\Moxir_Coder\AppData\Local\Programs\Python\Python311\Lib\site-packages\werkzeug\serving.py", line 370, in run_wsgi
    execute(self.server.app)
  File "C:\Users\Moxir_Coder\AppData\Local\Programs\Python\Python311\Lib\site-packages\werkzeug\serving.py", line 355, in execute
    data = self.rfile.read(10_000_000)
           ^^^^^^^^^^^^^^^^^^^^^^^^^^^
MemoryError
2025-09-28 21:50:28,738 | ERROR | werkzeug | _log:97 | Error on request:
Traceback (most recent call last):
  File "C:\Users\Moxir_Coder\AppData\Local\Programs\Python\Python311\Lib\site-packages\werkzeug\serving.py", line 370, in run_wsgi
    execute(self.server.app)
  File "C:\Users\Moxir_Coder\AppData\Local\Programs\Python\Python311\Lib\site-packages\werkzeug\serving.py", line 355, in execute
    data = self.rfile.read(10_000_000)
           ^^^^^^^^^^^^^^^^^^^^^^^^^^^
MemoryError
2025-09-28 21:50:28,743 | ERROR | werkzeug | _log:97 | Error on request:
Traceback (most recent call last):
  File "C:\Users\Moxir_Coder\AppData\Local\Programs\Python\Python311\Lib\site-packages\werkzeug\serving.py", line 370, in run_wsgi
    execute(self.server.app)
  File "C:\Users\Moxir_Coder\AppData\Local\Programs\Python\Python311\Lib\site-packages\werkzeug\serving.py", line 355, in execute
    data = self.rfile.read(10_000_000)
           ^^^^^^^^^^^^^^^^^^^^^^^^^^^
MemoryError
2025-09-28 21:50:28,753 | ERROR | werkzeug | _log:97 | Error on request:
Traceback (most recent call last):
  File "C:\Users\Moxir_Coder\AppData\Local\Programs\Python\Python311\Lib\site-packages\werkzeug\serving.py", line 370, in run_wsgi
    execute(self.server.app)
  File "C:\Users\Moxir_Coder\AppData\Local\Programs\Python\Python311\Lib\site-packages\werkzeug\serving.py", line 355, in execute
    data = self.rfile.read(10_000_000)
           ^^^^^^^^^^^^^^^^^^^^^^^^^^^
MemoryError
2025-09-28 21:50:28,764 | ERROR | werkzeug | _log:97 | Error on request:
Traceback (most recent call last):
  File "C:\Users\Moxir_Coder\AppData\Local\Programs\Python\Python311\Lib\site-packages\werkzeug\serving.py", line 370, in run_wsgi
    execute(self.server.app)
  File "C:\Users\Moxir_Coder\AppData\Local\Programs\Python\Python311\Lib\site-packages\werkzeug\serving.py", line 355, in execute
    data = self.rfile.read(10_000_000)
           ^^^^^^^^^^^^^^^^^^^^^^^^^^^
MemoryError
2025-09-28 21:50:28,773 | ERROR | werkzeug | _log:97 | Error on request:
Traceback (most recent call last):
  File "C:\Users\Moxir_Coder\AppData\Local\Programs\Python\Python311\Lib\site-packages\werkzeug\serving.py", line 370, in run_wsgi
    execute(self.server.app)
  File "C:\Users\Moxir_Coder\AppData\Local\Programs\Python\Python311\Lib\site-packages\werkzeug\serving.py", line 355, in execute
    data = self.rfile.read(10_000_000)
           ^^^^^^^^^^^^^^^^^^^^^^^^^^^
MemoryError
2025-09-28 21:50:28,782 | ERROR | werkzeug | _log:97 | Error on request:
Traceback (most recent call last):
  File "C:\Users\Moxir_Coder\AppData\Local\Programs\Python\Python311\Lib\site-packages\werkzeug\serving.py", line 370, in run_wsgi
    execute(self.server.app)
  File "C:\Users\Moxir_Coder\AppData\Local\Programs\Python\Python311\Lib\site-packages\werkzeug\serving.py", line 355, in execute
    data = self.rfile.read(10_000_000)
           ^^^^^^^^^^^^^^^^^^^^^^^^^^^
MemoryError
2025-09-28 21:50:28,793 | ERROR | werkzeug | _log:97 | Error on request:
Traceback (most recent call last):
  File "C:\Users\Moxir_Coder\AppData\Local\Programs\Python\Python311\Lib\site-packages\werkzeug\serving.py", line 370, in run_wsgi
    execute(self.server.app)
  File "C:\Users\Moxir_Coder\AppData\Local\Programs\Python\Python311\Lib\site-packages\werkzeug\serving.py", line 355, in execute
    data = self.rfile.read(10_000_000)
           ^^^^^^^^^^^^^^^^^^^^^^^^^^^
MemoryError
2025-09-28 21:50:28,804 | ERROR | werkzeug | _log:97 | Error on request:
Traceback (most recent call last):
  File "C:\Users\Moxir_Coder\AppData\Local\Programs\Python\Python311\Lib\site-packages\werkzeug\serving.py", line 370, in run_wsgi
    execute(self.server.app)
  File "C:\Users\Moxir_Coder\AppData\Local\Programs\Python\Python311\Lib\site-packages\werkzeug\serving.py", line 355, in execute
    data = self.rfile.read(10_000_000)
           ^^^^^^^^^^^^^^^^^^^^^^^^^^^
MemoryError
2025-09-28 21:50:28,826 | ERROR | werkzeug | _log:97 | Error on request:
Traceback (most recent call last):
  File "C:\Users\Moxir_Coder\AppData\Local\Programs\Python\Python311\Lib\site-packages\werkzeug\serving.py", line 370, in run_wsgi
    execute(self.server.app)
  File "C:\Users\Moxir_Coder\AppData\Local\Programs\Python\Python311\Lib\site-packages\werkzeug\serving.py", line 355, in execute
    data = self.rfile.read(10_000_000)
           ^^^^^^^^^^^^^^^^^^^^^^^^^^^
MemoryError
2025-09-28 21:50:28,870 | ERROR | werkzeug | _log:97 | Error on request:
Traceback (most recent call last):
  File "C:\Users\Moxir_Coder\AppData\Local\Programs\Python\Python311\Lib\site-packages\werkzeug\serving.py", line 370, in run_wsgi
    execute(self.server.app)
  File "C:\Users\Moxir_Coder\AppData\Local\Programs\Python\Python311\Lib\site-packages\werkzeug\serving.py", line 355, in execute
    data = self.rfile.read(10_000_000)
           ^^^^^^^^^^^^^^^^^^^^^^^^^^^
MemoryError
2025-09-28 21:50:28,884 | ERROR | werkzeug | _log:97 | Error on request:
Traceback (most recent call last):
  File "C:\Users\Moxir_Coder\AppData\Local\Programs\Python\Python311\Lib\site-packages\werkzeug\serving.py", line 370, in run_wsgi
    execute(self.server.app)
  File "C:\Users\Moxir_Coder\AppData\Local\Programs\Python\Python311\Lib\site-packages\werkzeug\serving.py", line 355, in execute
    data = self.rfile.read(10_000_000)
           ^^^^^^^^^^^^^^^^^^^^^^^^^^^
MemoryError
2025-09-28 21:50:28,908 | ERROR | werkzeug | _log:97 | Error on request:
Traceback (most recent call last):
  File "C:\Users\Moxir_Coder\AppData\Local\Programs\Python\Python311\Lib\site-packages\werkzeug\serving.py", line 370, in run_wsgi
    execute(self.server.app)
  File "C:\Users\Moxir_Coder\AppData\Local\Programs\Python\Python311\Lib\site-packages\werkzeug\serving.py", line 355, in execute
    data = self.rfile.read(10_000_000)
           ^^^^^^^^^^^^^^^^^^^^^^^^^^^
MemoryError
2025-09-28 21:50:28,932 | ERROR | werkzeug | _log:97 | Error on request:
Traceback (most recent call last):
  File "C:\Users\Moxir_Coder\AppData\Local\Programs\Python\Python311\Lib\site-packages\werkzeug\serving.py", line 370, in run_wsgi
    execute(self.server.app)
  File "C:\Users\Moxir_Coder\AppData\Local\Programs\Python\Python311\Lib\site-packages\werkzeug\serving.py", line 355, in execute
    data = self.rfile.read(10_000_000)
           ^^^^^^^^^^^^^^^^^^^^^^^^^^^
MemoryError
2025-09-28 21:50:28,955 | ERROR | werkzeug | _log:97 | Error on request:
Traceback (most recent call last):
  File "C:\Users\Moxir_Coder\AppData\Local\Programs\Python\Python311\Lib\site-packages\werkzeug\serving.py", line 370, in run_wsgi
    execute(self.server.app)
  File "C:\Users\Moxir_Coder\AppData\Local\Programs\Python\Python311\Lib\site-packages\werkzeug\serving.py", line 355, in execute
    data = self.rfile.read(10_000_000)
           ^^^^^^^^^^^^^^^^^^^^^^^^^^^
MemoryError
2025-09-28 21:50:28,977 | ERROR | werkzeug | _log:97 | Error on request:
Traceback (most recent call last):
  File "C:\Users\Moxir_Coder\AppData\Local\Programs\Python\Python311\Lib\site-packages\werkzeug\serving.py", line 370, in run_wsgi
    execute(self.server.app)
  File "C:\Users\Moxir_Coder\AppData\Local\Programs\Python\Python311\Lib\site-packages\werkzeug\serving.py", line 355, in execute
    data = self.rfile.read(10_000_000)
           ^^^^^^^^^^^^^^^^^^^^^^^^^^^
MemoryError
2025-09-28 21:50:29,010 | ERROR | werkzeug | _log:97 | Error on request:
Traceback (most recent call last):
  File "C:\Users\Moxir_Coder\AppData\Local\Programs\Python\Python311\Lib\site-packages\werkzeug\serving.py", line 370, in run_wsgi
    execute(self.server.app)
  File "C:\Users\Moxir_Coder\AppData\Local\Programs\Python\Python311\Lib\site-packages\werkzeug\serving.py", line 355, in execute
    data = self.rfile.read(10_000_000)
           ^^^^^^^^^^^^^^^^^^^^^^^^^^^
MemoryError
2025-09-28 21:55:00,052 | ERROR | werkzeug | _log:97 | Error on request:
Traceback (most recent call last):
  File "C:\Users\Moxir_Coder\AppData\Local\Programs\Python\Python311\Lib\site-packages\werkzeug\serving.py", line 370, in run_wsgi
    execute(self.server.app)
  File "C:\Users\Moxir_Coder\AppData\Local\Programs\Python\Python311\Lib\site-packages\werkzeug\serving.py", line 355, in execute
    data = self.rfile.read(10_000_000)
           ^^^^^^^^^^^^^^^^^^^^^^^^^^^
MemoryError
2025-09-28 21:55:00,076 | ERROR | werkzeug | _log:97 | Error on request:
Traceback (most recent call last):
  File "C:\Users\Moxir_Coder\AppData\Local\Programs\Python\Python311\Lib\site-packages\werkzeug\serving.py", line 370, in run_wsgi
    execute(self.server.app)
  File "C:\Users\Moxir_Coder\AppData\Local\Programs\Python\Python311\Lib\site-packages\werkzeug\serving.py", line 355, in execute
    data = self.rfile.read(10_000_000)
           ^^^^^^^^^^^^^^^^^^^^^^^^^^^
MemoryError
2025-09-28 21:55:00,129 | ERROR | werkzeug | _log:97 | Error on request:
Traceback (most recent call last):
  File "C:\Users\Moxir_Coder\AppData\Local\Programs\Python\Python311\Lib\site-packages\werkzeug\serving.py", line 370, in run_wsgi
    execute(self.server.app)
  File "C:\Users\Moxir_Coder\AppData\Local\Programs\Python\Python311\Lib\site-packages\werkzeug\serving.py", line 355, in execute
    data = self.rfile.read(10_000_000)
           ^^^^^^^^^^^^^^^^^^^^^^^^^^^
MemoryError
2025-09-28 21:55:00,148 | ERROR | werkzeug | _log:97 | Error on request:
Traceback (most recent call last):
  File "C:\Users\Moxir_Coder\AppData\Local\Programs\Python\Python311\Lib\site-packages\werkzeug\serving.py", line 370, in run_wsgi
    execute(self.server.app)
  File "C:\Users\Moxir_Coder\AppData\Local\Programs\Python\Python311\Lib\site-packages\werkzeug\serving.py", line 355, in execute
    data = self.rfile.read(10_000_000)
           ^^^^^^^^^^^^^^^^^^^^^^^^^^^
MemoryError
2025-09-28 21:55:00,162 | ERROR | werkzeug | _log:97 | Error on request:
Traceback (most recent call last):
  File "C:\Users\Moxir_Coder\AppData\Local\Programs\Python\Python311\Lib\site-packages\werkzeug\serving.py", line 370, in run_wsgi
    execute(self.server.app)
  File "C:\Users\Moxir_Coder\AppData\Local\Programs\Python\Python311\Lib\site-packages\werkzeug\serving.py", line 355, in execute
    data = self.rfile.read(10_000_000)
           ^^^^^^^^^^^^^^^^^^^^^^^^^^^
MemoryError
